Workbook
Name StartingBalance: #REF!

Sheet BACA DULU YUK! Panduan
B2: Template Spreadsheet Kaluna - Home Sweet Loan | I2: BACA
B5: Akses file master preview ini hanya view only. Pastikan untuk membuat duplikasi file terlebih dahulu: Desktop/laptop: Klik menu File > Make a copy/Buat Salinan Smartphone: Klik titik 3 pojok kanan > share and export > make a copy Abaikan pesan ini jika saat klik link pertama kali kamu sudah membuat duplikasi file.
B7: Tentang: | I7: DULU
B8: Template Budgeting Google Sheet ini dirancang dengan beragam fitur yang lengkap dan efisien untuk membantu kamu merencanakan dan mengatur alokasi keuangan dengan mudah. Dengan fitur-fitur yang komprehensif ini kamu dapat mengelola semua aset keuangan dalam satu file spreadsheet yang praktis. Informasi yang tertulis pada template yang diberikan hanya contoh dan silahkan sesuaikan isinya dengan kebutuhan kamu ya.
I11: YUK!
B12: Panduan: | C12: >> Format Video Di sini
B13: 1. Saat pertama kali menggunakan template ini, pastikan kamu menyesuaikan beberapa pengaturan umum pada sheet ⚙️Setup. Ubah semua daftar yang tersedia berdasarkan preferensimu (selain daftar nama bulan).
B14: 2. Setiap awal bulan, silahkan buat alokasi keuanganmu pada sheet Budgeting sesuai kolom bulan berjalan. Selain baris total, semua nominal pada sheet budgeting perlu kamu input secara manual.
B15: 3. Ketika sudah mengisi semua nominal pada list pengeluaran di sheet Budgeting, kamu dapat melihat ringkasan alokasi keuangan yang sudah dibuat pada sheet Summary. Hampir semua data pada sheet Summary sudah terisi otomatis. Kamu hanya cukup mengatur ulang list akun bank berdasarkan daftar pengeluaran pada kolom C. Untuk melihat ulang budgeting bulan per bulan, kamu dapat memilih menu list daftar bulan pada bagian atas. | I15: ⬅ | J15: ⬅ | K15: ⬅ | L15: ⬅
B16: 4. Pada sheet Spending, kamu dapat membuat rekap transaksi per kategorinya. Rekap ini tidak perlu kamu buat setiap hari. Pastikan juga untuk selalu menyesuaikan tanggal dan bulan transaksi agar data pengeluaran dapat direkap dengan benar. Jika berganti bulan, silahkan lanjutkan membuat daftar pengeluaran di bawah bulan sebelumnya. Cukup sesuaikan tanggal transaksinya saja.
B17: 5. Kamu dapat dengan mudah rekap catatan keuangan setiap bulannya lewat sheet Report. Pada sheet ini tersedia beragam laporan seperti: total pemasukan, jumlah tabungan, dan uang yang dialokasikan setiap bulannya. Kamu juga dapat dengan mudah melihat kembali ringkasan pengeluran per bulan, statistik pengeluaran berdasarkan kategori, serta status persentasi penggunaan uang berdasarkan alokasi budget yang sudah dibuat.
B18: 6. Sheet Assets berguna untuk mencatat semua total asset keuangan yang ada. Kamu bebas menambahkan sendiri assets dan tabungan berdasarkan kategori yang tersedia.
B19: 7. Sheet Snapsot (hidden) bisa kamu abaikan saja tapi jangan dihapus ya. Sheet ini digunakan untuk menyimpan sementara transaksi yang dicatat pada sheet yang terhubung.
B21: Catatan:
B22: ⚡Fitur ceklis yang tersedia pada sheet summary dan spending tidak memengaruhi formula maupun sheet lainnya. Ceklis ini hanya mempermudah untuk sortir transaksi.
B23: ⚡ Beberapa fitur pada spreadsheet ini kemungkinan belum support jika digunakan lewat aplikasi Excel. Untuk penggunaan maksimal, pastikan hanya melakukan editing lewat Google sheet.
B24: ⚡ Pro tips: pada sheet Summary, jika terdapat sub kategori yang tidak digunakan, boleh langsung dihapus per baris agar tidak ada area kosong tanpa data.
B25: ⚡ Untuk lebih banyak pertanyaan terkait fitur dan cara menggunakan template ini, boleh untuk mengirimkan email ke : tanyakaluna@gmail.com
B27: Oh iya, jangan menyebarkan link spreadsheet ini ya, karena ini khusus hanya untuk kamu para pejuang hidup yang udah nonton film HSL 💚
B29: *Template Google Spreadsheet ini kolaborasi Home Sweet Loan dan @andreqve

Sheet Report
B2: Money Management Dashboard | J2: Year: | K2: 2024 | L2: =MONTH(DATEVALUE(K3&" 1")) -> 1
J3: Month: | K3: January
E5: Montly Report 📊
B7: Total Income | E7: Budgeted Expenses | H7: Total Spending | K7: Monthly Savings
B8: {=INDEX(Budgeting!C10:N10, 1, MATCH(K3, Budgeting!C2:N2, 0)) + N("AndBV3")} -> 6943000 | E8: {=INDEX(Budgeting!$C$43:$N$43, 1, MATCH(K3, Budgeting!$C$2:$N$2, 0))} -> 3250000 | H8: {=SUMIFS(Spending!G:G, TEXT(Spending!C:C, "MM/YYYY"), TEXT(DATEVALUE("01/"&TEXT($K$3, "00")&"/"&$K$2), "MM/YYYY"))} -> 2033500 | K8: {=INDEX(Budgeting!$C$19:$N$19, 1, MATCH(K3, Budgeting!$C$2:$N$2, 0))} -> 343982000
B11: Expenses List | D11: Allocation 💰 | F11: Realization 💸 | H11: Budget Usage Progress | L11: % Usage
B12: =Budgeting!B23 -> Family | D12: {=IFERROR(INDEX(Budgeting!C$23:N$42, MATCH(B12, Budgeting!B$23:B$42, 0), MATCH($K$3, Budgeting!C$2:N$2, 0)), "")} -> 500000 | F12: {=SUMIFS(Spending!G:G, Spending!F:F, B12, TEXT(Spending!C:C, "MM/YYYY"), TEXT(DATEVALUE("01/"&TEXT($K$3, "00")&"/"&$K$2), "MM/YYYY"))} -> 0 | H12: =IFERROR(__xludf.DUMMYFUNCTION("IF(AND(F12<>"""", D12<>"""", MAX(D12)<>0), SPARKLINE(F12, { ""charttype"", ""bar""; ""max"", MAX(D12); ""color1"", IF(F12/MAX(D12)<0.7, ""#C3EDC0"", IF(F12/MAX(D12)>=0.7, IF(F12/MAX(D12)<1, ""#F9F3CC"", ""#FCC8D1""), ""00b88c"""&")) } ), """") "),"") | L12: =IFERROR(F12/D12,0) -> 0
B13: =Budgeting!B24 -> Utilities | D13: {=IFERROR(INDEX(Budgeting!C$23:N$42, MATCH(B13, Budgeting!B$23:B$42, 0), MATCH($K$3, Budgeting!C$2:N$2, 0)), "")} -> 500000 | F13: {=SUMIFS(Spending!G:G, Spending!F:F, B13, TEXT(Spending!C:C, "MM/YYYY"), TEXT(DATEVALUE("01/"&TEXT($K$3, "00")&"/"&$K$2), "MM/YYYY"))} -> 500000 | H13: =IFERROR(__xludf.DUMMYFUNCTION("IF(AND(F13<>"""", D13<>"""", MAX(D13)<>0), SPARKLINE(F13, { ""charttype"", ""bar""; ""max"", MAX(D13); ""color1"", IF(F13/MAX(D13)<0.7, ""#C3EDC0"", IF(F13/MAX(D13)>=0.7, IF(F13/MAX(D13)<1, ""#F9F3CC"", ""#FCC8D1""), ""00b88c"""&")) } ), """") "),"") | L13: =IFERROR(F13/D13,0) -> 1
B14: =Budgeting!B25 -> Food | D14: {=IFERROR(INDEX(Budgeting!C$23:N$42, MATCH(B14, Budgeting!B$23:B$42, 0), MATCH($K$3, Budgeting!C$2:N$2, 0)), "")} -> 600000 | F14: {=SUMIFS(Spending!G:G, Spending!F:F, B14, TEXT(Spending!C:C, "MM/YYYY"), TEXT(DATEVALUE("01/"&TEXT($K$3, "00")&"/"&$K$2), "MM/YYYY"))} -> 473000 | H14: =IFERROR(__xludf.DUMMYFUNCTION("IF(AND(F14<>"""", D14<>"""", MAX(D14)<>0), SPARKLINE(F14, { ""charttype"", ""bar""; ""max"", MAX(D14); ""color1"", IF(F14/MAX(D14)<0.7, ""#C3EDC0"", IF(F14/MAX(D14)>=0.7, IF(F14/MAX(D14)<1, ""#F9F3CC"", ""#FCC8D1""), ""00b88c"""&")) } ), """") "),"") | L14: =IFERROR(F14/D14,0) -> 0.78833333
B15: =Budgeting!B26 -> Supplies | D15: {=IFERROR(INDEX(Budgeting!C$23:N$42, MATCH(B15, Budgeting!B$23:B$42, 0), MATCH($K$3, Budgeting!C$2:N$2, 0)), "")} -> 500000 | F15: {=SUMIFS(Spending!G:G, Spending!F:F, B15, TEXT(Spending!C:C, "MM/YYYY"), TEXT(DATEVALUE("01/"&TEXT($K$3, "00")&"/"&$K$2), "MM/YYYY"))} -> 400000 | H15: =IFERROR(__xludf.DUMMYFUNCTION("IF(AND(F15<>"""", D15<>"""", MAX(D15)<>0), SPARKLINE(F15, { ""charttype"", ""bar""; ""max"", MAX(D15); ""color1"", IF(F15/MAX(D15)<0.7, ""#C3EDC0"", IF(F15/MAX(D15)>=0.7, IF(F15/MAX(D15)<1, ""#F9F3CC"", ""#FCC8D1""), ""00b88c"""&")) } ), """") "),"") | L15: =IFERROR(F15/D15,0) -> 0.8
B16: =Budgeting!B27 -> Transportation | D16: {=IFERROR(INDEX(Budgeting!C$23:N$42, MATCH(B16, Budgeting!B$23:B$42, 0), MATCH($K$3, Budgeting!C$2:N$2, 0)), "")} -> 400000 | F16: {=SUMIFS(Spending!G:G, Spending!F:F, B16, TEXT(Spending!C:C, "MM/YYYY"), TEXT(DATEVALUE("01/"&TEXT($K$3, "00")&"/"&$K$2), "MM/YYYY"))} -> 382500 | H16: =IFERROR(__xludf.DUMMYFUNCTION("IF(AND(F16<>"""", D16<>"""", MAX(D16)<>0), SPARKLINE(F16, { ""charttype"", ""bar""; ""max"", MAX(D16); ""color1"", IF(F16/MAX(D16)<0.7, ""#C3EDC0"", IF(F16/MAX(D16)>=0.7, IF(F16/MAX(D16)<1, ""#F9F3CC"", ""#FCC8D1""), ""00b88c"""&")) } ), """") "),"") | L16: =IFERROR(F16/D16,0) -> 0.95625
B17: =Budgeting!B28 -> Healthcare | D17: {=IFERROR(INDEX(Budgeting!C$23:N$42, MATCH(B17, Budgeting!B$23:B$42, 0), MATCH($K$3, Budgeting!C$2:N$2, 0)), "")} -> 200000 | F17: {=SUMIFS(Spending!G:G, Spending!F:F, B17, TEXT(Spending!C:C, "MM/YYYY"), TEXT(DATEVALUE("01/"&TEXT($K$3, "00")&"/"&$K$2), "MM/YYYY"))} -> 100000 | H17: =IFERROR(__xludf.DUMMYFUNCTION("IF(AND(F17<>"""", D17<>"""", MAX(D17)<>0), SPARKLINE(F17, { ""charttype"", ""bar""; ""max"", MAX(D17); ""color1"", IF(F17/MAX(D17)<0.7, ""#C3EDC0"", IF(F17/MAX(D17)>=0.7, IF(F17/MAX(D17)<1, ""#F9F3CC"", ""#FCC8D1""), ""00b88c"""&")) } ), """") "),"") | L17: =IFERROR(F17/D17,0) -> 0.5
B18: =Budgeting!B29 -> Debt | D18: {=IFERROR(INDEX(Budgeting!C$23:N$42, MATCH(B18, Budgeting!B$23:B$42, 0), MATCH($K$3, Budgeting!C$2:N$2, 0)), "")} -> 0 | F18: {=SUMIFS(Spending!G:G, Spending!F:F, B18, TEXT(Spending!C:C, "MM/YYYY"), TEXT(DATEVALUE("01/"&TEXT($K$3, "00")&"/"&$K$2), "MM/YYYY"))} -> 0 | H18: =IFERROR(__xludf.DUMMYFUNCTION("IF(AND(F18<>"""", D18<>"""", MAX(D18)<>0), SPARKLINE(F18, { ""charttype"", ""bar""; ""max"", MAX(D18); ""color1"", IF(F18/MAX(D18)<0.7, ""#C3EDC0"", IF(F18/MAX(D18)>=0.7, IF(F18/MAX(D18)<1, ""#F9F3CC"", ""#FCC8D1""), ""00b88c"""&")) } ), """") "),"") | L18: =IFERROR(F18/D18,0) -> 0
B19: =Budgeting!B30 -> Needs 8 | D19: {=IFERROR(INDEX(Budgeting!C$23:N$42, MATCH(B19, Budgeting!B$23:B$42, 0), MATCH($K$3, Budgeting!C$2:N$2, 0)), "")} | F19: {=SUMIFS(Spending!G:G, Spending!F:F, B19, TEXT(Spending!C:C, "MM/YYYY"), TEXT(DATEVALUE("01/"&TEXT($K$3, "00")&"/"&$K$2), "MM/YYYY"))} -> 0 | H19: =IFERROR(__xludf.DUMMYFUNCTION("IF(AND(F19<>"""", D19<>"""", MAX(D19)<>0), SPARKLINE(F19, { ""charttype"", ""bar""; ""max"", MAX(D19); ""color1"", IF(F19/MAX(D19)<0.7, ""#C3EDC0"", IF(F19/MAX(D19)>=0.7, IF(F19/MAX(D19)<1, ""#F9F3CC"", ""#FCC8D1""), ""00b88c"""&")) } ), """") "),"") | L19: =IFERROR(F19/D19,0) -> 0
B20: =Budgeting!B31 -> Needs 9 | D20: {=IFERROR(INDEX(Budgeting!C$23:N$42, MATCH(B20, Budgeting!B$23:B$42, 0), MATCH($K$3, Budgeting!C$2:N$2, 0)), "")} | F20: {=SUMIFS(Spending!G:G, Spending!F:F, B20, TEXT(Spending!C:C, "MM/YYYY"), TEXT(DATEVALUE("01/"&TEXT($K$3, "00")&"/"&$K$2), "MM/YYYY"))} -> 0 | H20: =IFERROR(__xludf.DUMMYFUNCTION("IF(AND(F20<>"""", D20<>"""", MAX(D20)<>0), SPARKLINE(F20, { ""charttype"", ""bar""; ""max"", MAX(D20); ""color1"", IF(F20/MAX(D20)<0.7, ""#C3EDC0"", IF(F20/MAX(D20)>=0.7, IF(F20/MAX(D20)<1, ""#F9F3CC"", ""#FCC8D1""), ""00b88c"""&")) } ), """") "),"") | L20: =IFERROR(F20/D20,0) -> 0
B21: =Budgeting!B32 -> Needs 10 | D21: {=IFERROR(INDEX(Budgeting!C$23:N$42, MATCH(B21, Budgeting!B$23:B$42, 0), MATCH($K$3, Budgeting!C$2:N$2, 0)), "")} | F21: {=SUMIFS(Spending!G:G, Spending!F:F, B21, TEXT(Spending!C:C, "MM/YYYY"), TEXT(DATEVALUE("01/"&TEXT($K$3, "00")&"/"&$K$2), "MM/YYYY"))} -> 0 | H21: =IFERROR(__xludf.DUMMYFUNCTION("IF(AND(F21<>"""", D21<>"""", MAX(D21)<>0), SPARKLINE(F21, { ""charttype"", ""bar""; ""max"", MAX(D21); ""color1"", IF(F21/MAX(D21)<0.7, ""#C3EDC0"", IF(F21/MAX(D21)>=0.7, IF(F21/MAX(D21)<1, ""#F9F3CC"", ""#FCC8D1""), ""00b88c"""&")) } ), """") "),"") | L21: =IFERROR(F21/D21,0) -> 0
B22: =Budgeting!B33 -> Shopping | D22: {=IFERROR(INDEX(Budgeting!C$23:N$42, MATCH(B22, Budgeting!B$23:B$42, 0), MATCH($K$3, Budgeting!C$2:N$2, 0)), "")} -> 200000 | F22: {=SUMIFS(Spending!G:G, Spending!F:F, B22, TEXT(Spending!C:C, "MM/YYYY"), TEXT(DATEVALUE("01/"&TEXT($K$3, "00")&"/"&$K$2), "MM/YYYY"))} -> 0 | H22: =IFERROR(__xludf.DUMMYFUNCTION("IF(AND(F22<>"""", D22<>"""", MAX(D22)<>0), SPARKLINE(F22, { ""charttype"", ""bar""; ""max"", MAX(D22); ""color1"", IF(F22/MAX(D22)<0.7, ""#C3EDC0"", IF(F22/MAX(D22)>=0.7, IF(F22/MAX(D22)<1, ""#F9F3CC"", ""#FCC8D1""), ""00b88c"""&")) } ), """") "),"") | L22: =IFERROR(F22/D22,0) -> 0
B23: =Budgeting!B34 -> Entertaiment | D23: {=IFERROR(INDEX(Budgeting!C$23:N$42, MATCH(B23, Budgeting!B$23:B$42, 0), MATCH($K$3, Budgeting!C$2:N$2, 0)), "")} -> 200000 | F23: {=SUMIFS(Spending!G:G, Spending!F:F, B23, TEXT(Spending!C:C, "MM/YYYY"), TEXT(DATEVALUE("01/"&TEXT($K$3, "00")&"/"&$K$2), "MM/YYYY"))} -> 178000 | H23: =IFERROR(__xludf.DUMMYFUNCTION("IF(AND(F23<>"""", D23<>"""", MAX(D23)<>0), SPARKLINE(F23, { ""charttype"", ""bar""; ""max"", MAX(D23); ""color1"", IF(F23/MAX(D23)<0.7, ""#C3EDC0"", IF(F23/MAX(D23)>=0.7, IF(F23/MAX(D23)<1, ""#F9F3CC"", ""#FCC8D1""), ""00b88c"""&")) } ), """") "),"") | L23: =IFERROR(F23/D23,0) -> 0.89
B24: =Budgeting!B35 -> Gifts | D24: {=IFERROR(INDEX(Budgeting!C$23:N$42, MATCH(B24, Budgeting!B$23:B$42, 0), MATCH($K$3, Budgeting!C$2:N$2, 0)), "")} -> 150000 | F24: {=SUMIFS(Spending!G:G, Spending!F:F, B24, TEXT(Spending!C:C, "MM/YYYY"), TEXT(DATEVALUE("01/"&TEXT($K$3, "00")&"/"&$K$2), "MM/YYYY"))} -> 0 | H24: =IFERROR(__xludf.DUMMYFUNCTION("IF(AND(F24<>"""", D24<>"""", MAX(D24)<>0), SPARKLINE(F24, { ""charttype"", ""bar""; ""max"", MAX(D24); ""color1"", IF(F24/MAX(D24)<0.7, ""#C3EDC0"", IF(F24/MAX(D24)>=0.7, IF(F24/MAX(D24)<1, ""#F9F3CC"", ""#FCC8D1""), ""00b88c"""&")) } ), """") "),"") | L24: =IFERROR(F24/D24,0) -> 0
B25: =Budgeting!B36 -> Travel | D25: {=IFERROR(INDEX(Budgeting!C$23:N$42, MATCH(B25, Budgeting!B$23:B$42, 0), MATCH($K$3, Budgeting!C$2:N$2, 0)), "")} | F25: {=SUMIFS(Spending!G:G, Spending!F:F, B25, TEXT(Spending!C:C, "MM/YYYY"), TEXT(DATEVALUE("01/"&TEXT($K$3, "00")&"/"&$K$2), "MM/YYYY"))} -> 0 | H25: =IFERROR(__xludf.DUMMYFUNCTION("IF(AND(F25<>"""", D25<>"""", MAX(D25)<>0), SPARKLINE(F25, { ""charttype"", ""bar""; ""max"", MAX(D25); ""color1"", IF(F25/MAX(D25)<0.7, ""#C3EDC0"", IF(F25/MAX(D25)>=0.7, IF(F25/MAX(D25)<1, ""#F9F3CC"", ""#FCC8D1""), ""00b88c"""&")) } ), """") "),"") | L25: =IFERROR(F25/D25,0) -> 0
B26: =Budgeting!B37 -> Wants 5 | D26: {=IFERROR(INDEX(Budgeting!C$23:N$42, MATCH(B26, Budgeting!B$23:B$42, 0), MATCH($K$3, Budgeting!C$2:N$2, 0)), "")} | F26: {=SUMIFS(Spending!G:G, Spending!F:F, B26, TEXT(Spending!C:C, "MM/YYYY"), TEXT(DATEVALUE("01/"&TEXT($K$3, "00")&"/"&$K$2), "MM/YYYY"))} -> 0 | H26: =IFERROR(__xludf.DUMMYFUNCTION("IF(AND(F26<>"""", D26<>"""", MAX(D26)<>0), SPARKLINE(F26, { ""charttype"", ""bar""; ""max"", MAX(D26); ""color1"", IF(F26/MAX(D26)<0.7, ""#C3EDC0"", IF(F26/MAX(D26)>=0.7, IF(F26/MAX(D26)<1, ""#F9F3CC"", ""#FCC8D1""), ""00b88c"""&")) } ), """") "),"") | L26: =IFERROR(F26/D26,0) -> 0
B27: =Budgeting!B38 -> Wants 6 | D27: {=IFERROR(INDEX(Budgeting!C$23:N$42, MATCH(B27, Budgeting!B$23:B$42, 0), MATCH($K$3, Budgeting!C$2:N$2, 0)), "")} | F27: {=SUMIFS(Spending!G:G, Spending!F:F, B27, TEXT(Spending!C:C, "MM/YYYY"), TEXT(DATEVALUE("01/"&TEXT($K$3, "00")&"/"&$K$2), "MM/YYYY"))} -> 0 | H27: =IFERROR(__xludf.DUMMYFUNCTION("IF(AND(F27<>"""", D27<>"""", MAX(D27)<>0), SPARKLINE(F27, { ""charttype"", ""bar""; ""max"", MAX(D27); ""color1"", IF(F27/MAX(D27)<0.7, ""#C3EDC0"", IF(F27/MAX(D27)>=0.7, IF(F27/MAX(D27)<1, ""#F9F3CC"", ""#FCC8D1""), ""00b88c"""&")) } ), """") "),"") | L27: =IFERROR(F27/D27,0) -> 0
B28: =Budgeting!B39 -> Wants 7 | D28: {=IFERROR(INDEX(Budgeting!C$23:N$42, MATCH(B28, Budgeting!B$23:B$42, 0), MATCH($K$3, Budgeting!C$2:N$2, 0)), "")} | F28: {=SUMIFS(Spending!G:G, Spending!F:F, B28, TEXT(Spending!C:C, "MM/YYYY"), TEXT(DATEVALUE("01/"&TEXT($K$3, "00")&"/"&$K$2), "MM/YYYY"))} -> 0 | H28: =IFERROR(__xludf.DUMMYFUNCTION("IF(AND(F28<>"""", D28<>"""", MAX(D28)<>0), SPARKLINE(F28, { ""charttype"", ""bar""; ""max"", MAX(D28); ""color1"", IF(F28/MAX(D28)<0.7, ""#C3EDC0"", IF(F28/MAX(D28)>=0.7, IF(F28/MAX(D28)<1, ""#F9F3CC"", ""#FCC8D1""), ""00b88c"""&")) } ), """") "),"") | L28: =IFERROR(F28/D28,0) -> 0
B29: =Budgeting!B40 -> Wants 8 | D29: {=IFERROR(INDEX(Budgeting!C$23:N$42, MATCH(B29, Budgeting!B$23:B$42, 0), MATCH($K$3, Budgeting!C$2:N$2, 0)), "")} | F29: {=SUMIFS(Spending!G:G, Spending!F:F, B29, TEXT(Spending!C:C, "MM/YYYY"), TEXT(DATEVALUE("01/"&TEXT($K$3, "00")&"/"&$K$2), "MM/YYYY"))} -> 0 | H29: =IFERROR(__xludf.DUMMYFUNCTION("IF(AND(F29<>"""", D29<>"""", MAX(D29)<>0), SPARKLINE(F29, { ""charttype"", ""bar""; ""max"", MAX(D29); ""color1"", IF(F29/MAX(D29)<0.7, ""#C3EDC0"", IF(F29/MAX(D29)>=0.7, IF(F29/MAX(D29)<1, ""#F9F3CC"", ""#FCC8D1""), ""00b88c"""&")) } ), """") "),"") | L29: =IFERROR(F29/D29,0) -> 0
B30: =Budgeting!B41 -> Wants 9 | D30: {=IFERROR(INDEX(Budgeting!C$23:N$42, MATCH(B30, Budgeting!B$23:B$42, 0), MATCH($K$3, Budgeting!C$2:N$2, 0)), "")} | F30: {=SUMIFS(Spending!G:G, Spending!F:F, B30, TEXT(Spending!C:C, "MM/YYYY"), TEXT(DATEVALUE("01/"&TEXT($K$3, "00")&"/"&$K$2), "MM/YYYY"))} -> 0 | H30: =IFERROR(__xludf.DUMMYFUNCTION("IF(AND(F30<>"""", D30<>"""", MAX(D30)<>0), SPARKLINE(F30, { ""charttype"", ""bar""; ""max"", MAX(D30); ""color1"", IF(F30/MAX(D30)<0.7, ""#C3EDC0"", IF(F30/MAX(D30)>=0.7, IF(F30/MAX(D30)<1, ""#F9F3CC"", ""#FCC8D1""), ""00b88c"""&")) } ), """") "),"") | L30: =IFERROR(F30/D30,0) -> 0
B31: =Budgeting!B42 -> Wants 10 | D31: {=IFERROR(INDEX(Budgeting!C$23:N$42, MATCH(B31, Budgeting!B$23:B$42, 0), MATCH($K$3, Budgeting!C$2:N$2, 0)), "")} | F31: {=SUMIFS(Spending!G:G, Spending!F:F, B31, TEXT(Spending!C:C, "MM/YYYY"), TEXT(DATEVALUE("01/"&TEXT($K$3, "00")&"/"&$K$2), "MM/YYYY"))} -> 0 | H31: =IFERROR(__xludf.DUMMYFUNCTION("IF(AND(F31<>"""", D31<>"""", MAX(D31)<>0), SPARKLINE(F31, { ""charttype"", ""bar""; ""max"", MAX(D31); ""color1"", IF(F31/MAX(D31)<0.7, ""#C3EDC0"", IF(F31/MAX(D31)>=0.7, IF(F31/MAX(D31)<1, ""#F9F3CC"", ""#FCC8D1""), ""00b88c"""&")) } ), """") "),"") | L31: =IFERROR(F31/D31,0) -> 0
B34: Expense Realization Percentage | H34: Monthly Expense Trend

Sheet Summary
B2: =TODAY() -> 46317 | F2: =IF(TODAY() = '⚙️Setup'!I3, "Today is payday!", "💰 The next payday is in " & IF(DAY(TODAY()) <= DAY('⚙️Setup'!I3), DAY('⚙️Setup'!I3) - DAY(TODAY()), DAY(EOMONTH(TODAY(),0)) - DAY(TODAY()) + DAY('⚙️Setup'!I3)) & " days") -> 💰 The next payday is in 3 days | J2: Month ➠ | K2: January
B4: Budgeting Summary Sheet
B6: ='⚙️Setup'!B3 -> BCA | D6: =SUMPRODUCT($J$13:$J$36,$C$13:$C$36=B6) -> 13100000 | F6: Needs | H6: =SUMPRODUCT($J$13:$J$36,$H$13:$H$36=F6) -> 2700000 | J6: Total Income | K6: {=INDEX(Budgeting!C10:N10, 1, MATCH(K2, Budgeting!C2:N2, 0))} -> 6943000
B7: ='⚙️Setup'!B4 -> Account 2 | D7: =SUMPRODUCT($J$13:$J$36,$C$13:$C$36=B7) -> 5150000 | F7: Wants | H7: =SUMPRODUCT($J$13:$J$36,$H$13:$H$36=F7) -> 550000 | J7: Non-allocated | K7: =K6-SUM(H6:H8) -> -340289000
B8: ='⚙️Setup'!B5 -> Account 3 | D8: =SUMPRODUCT($J$13:$J$36,$C$13:$C$36=B8) -> 328982000 | F8: Savings | H8: =SUMPRODUCT($J$13:$J$36,$H$13:$H$36=F8) -> 343982000 | J8: Usage Percentage | K8: =SUM(K13:K36) -> 50.01181
B10: Account | D10: Expenses List | H10: Main Category | J10: Allocation | K10: Percentage
B12: ✓
B13: FALSE | C13: BCA | D13: =Budgeting!B13 -> General Savings | G13: {=INDEX('⚙️Setup'!$D$2:$F$2, MAX(IF('⚙️Setup'!$D$3:$F$25=D13, COLUMN('⚙️Setup'!$D$3:$F$25)-COLUMN('⚙️Setup'!$D$3)+1)))} -> Savings | H13: =G13 -> Savings | J13: {=IFERROR(INDEX(Budgeting!$C$5:$N$42, MATCH(D13, Budgeting!$B$5:$B$42, 0), MATCH($K$2, Budgeting!$C$2:$N$2, 0)), 0)} -> 10000000 | K13: =IFERROR(J13/$K$6, 0) -> 1.4402996
B14: FALSE | C14: Account 2 | D14: =Budgeting!B14 -> Emergency Funds | G14: {=INDEX('⚙️Setup'!$D$2:$F$2, MAX(IF('⚙️Setup'!$D$3:$F$25=D14, COLUMN('⚙️Setup'!$D$3:$F$25)-COLUMN('⚙️Setup'!$D$3)+1)))} -> Savings | H14: =G14 -> Savings | J14: {=IFERROR(INDEX(Budgeting!$C$5:$N$42, MATCH(D14, Budgeting!$B$5:$B$42, 0), MATCH($K$2, Budgeting!$C$2:$N$2, 0)), 0)} -> 5000000 | K14: =IFERROR(J14/$K$6, 0) -> 0.72014979
B15: FALSE | C15: Account 3 | D15: =Budgeting!B15 -> Deposits | G15: {=INDEX('⚙️Setup'!$D$2:$F$2, MAX(IF('⚙️Setup'!$D$3:$F$25=D15, COLUMN('⚙️Setup'!$D$3:$F$25)-COLUMN('⚙️Setup'!$D$3)+1)))} -> Savings | H15: =G15 -> Savings | J15: {=IFERROR(INDEX(Budgeting!$C$5:$N$42, MATCH(D15, Budgeting!$B$5:$B$42, 0), MATCH($K$2, Budgeting!$C$2:$N$2, 0)), 0)} -> 328982000 | K15: =IFERROR(J15/$K$6, 0) -> 47.383264
B16: FALSE | C16: Account 2 | D16: =Budgeting!B17 -> Savings 4 | G16: {=INDEX('⚙️Setup'!$D$2:$F$2, MAX(IF('⚙️Setup'!$D$3:$F$25=D16, COLUMN('⚙️Setup'!$D$3:$F$25)-COLUMN('⚙️Setup'!$D$3)+1)))} -> Savings | H16: =G16 -> Savings | J16: {=IFERROR(INDEX(Budgeting!$C$5:$N$42, MATCH(D16, Budgeting!$B$5:$B$42, 0), MATCH($K$2, Budgeting!$C$2:$N$2, 0)), 0)} | K16: =IFERROR(J16/$K$6, 0) -> 0
B17: FALSE | C17: Account 3 | D17: =Budgeting!B18 -> Savings 5 | G17: {=INDEX('⚙️Setup'!$D$2:$F$2, MAX(IF('⚙️Setup'!$D$3:$F$25=D17, COLUMN('⚙️Setup'!$D$3:$F$25)-COLUMN('⚙️Setup'!$D$3)+1)))} -> Savings | H17: =G17 -> Savings | J17: {=IFERROR(INDEX(Budgeting!$C$5:$N$42, MATCH(D17, Budgeting!$B$5:$B$42, 0), MATCH($K$2, Budgeting!$C$2:$N$2, 0)), 0)} | K17: =IFERROR(J17/$K$6, 0) -> 0
B18: FALSE | C18: BCA | D18: =Budgeting!B23 -> Family | G18: {=INDEX('⚙️Setup'!$D$2:$F$2, MAX(IF('⚙️Setup'!$D$3:$F$25=D18, COLUMN('⚙️Setup'!$D$3:$F$25)-COLUMN('⚙️Setup'!$D$3)+1)))} -> Needs | H18: =G18 -> Needs | J18: {=IFERROR(INDEX(Budgeting!$C$5:$N$42, MATCH(D18, Budgeting!$B$5:$B$42, 0), MATCH($K$2, Budgeting!$C$2:$N$2, 0)), 0)} -> 500000 | K18: =IFERROR(J18/$K$6, 0) -> 0.072014979
B19: FALSE | C19: BCA | D19: =Budgeting!B24 -> Utilities | G19: {=INDEX('⚙️Setup'!$D$2:$F$2, MAX(IF('⚙️Setup'!$D$3:$F$25=D19, COLUMN('⚙️Setup'!$D$3:$F$25)-COLUMN('⚙️Setup'!$D$3)+1)))} -> Needs | H19: =G19 -> Needs | J19: {=IFERROR(INDEX(Budgeting!$C$5:$N$42, MATCH(D19, Budgeting!$B$5:$B$42, 0), MATCH($K$2, Budgeting!$C$2:$N$2, 0)), 0)} -> 500000 | K19: =IFERROR(J19/$K$6, 0) -> 0.072014979
B20: FALSE | C20: BCA | D20: =Budgeting!B25 -> Food | G20: {=INDEX('⚙️Setup'!$D$2:$F$2, MAX(IF('⚙️Setup'!$D$3:$F$25=D20, COLUMN('⚙️Setup'!$D$3:$F$25)-COLUMN('⚙️Setup'!$D$3)+1)))} -> Needs | H20: =G20 -> Needs | J20: {=IFERROR(INDEX(Budgeting!$C$5:$N$42, MATCH(D20, Budgeting!$B$5:$B$42, 0), MATCH($K$2, Budgeting!$C$2:$N$2, 0)), 0)+ N("AndBV3")} -> 600000 | K20: =IFERROR(J20/$K$6, 0) -> 0.086417975
B21: FALSE | C21: BCA | D21: =Budgeting!B26 -> Supplies | G21: {=INDEX('⚙️Setup'!$D$2:$F$2, MAX(IF('⚙️Setup'!$D$3:$F$25=D21, COLUMN('⚙️Setup'!$D$3:$F$25)-COLUMN('⚙️Setup'!$D$3)+1)))} -> Needs | H21: =G21 -> Needs | J21: {=IFERROR(INDEX(Budgeting!$C$5:$N$42, MATCH(D21, Budgeting!$B$5:$B$42, 0), MATCH($K$2, Budgeting!$C$2:$N$2, 0)), 0)} -> 500000 | K21: =IFERROR(J21/$K$6, 0) -> 0.072014979
B22: FALSE | C22: BCA | D22: =Budgeting!B27 -> Transportation | G22: {=INDEX('⚙️Setup'!$D$2:$F$2, MAX(IF('⚙️Setup'!$D$3:$F$25=D22, COLUMN('⚙️Setup'!$D$3:$F$25)-COLUMN('⚙️Setup'!$D$3)+1)))} -> Needs | H22: =G22 -> Needs | J22: {=IFERROR(INDEX(Budgeting!$C$5:$N$42, MATCH(D22, Budgeting!$B$5:$B$42, 0), MATCH($K$2, Budgeting!$C$2:$N$2, 0)), 0)} -> 400000 | K22: =IFERROR(J22/$K$6, 0) -> 0.057611983
B23: FALSE | C23: BCA | D23: =Budgeting!B28 -> Healthcare | G23: {=INDEX('⚙️Setup'!$D$2:$F$2, MAX(IF('⚙️Setup'!$D$3:$F$25=D23, COLUMN('⚙️Setup'!$D$3:$F$25)-COLUMN('⚙️Setup'!$D$3)+1)))} -> Needs | H23: =G23 -> Needs | J23: {=IFERROR(INDEX(Budgeting!$C$5:$N$42, MATCH(D23, Budgeting!$B$5:$B$42, 0), MATCH($K$2, Budgeting!$C$2:$N$2, 0)), 0)} -> 200000 | K23: =IFERROR(J23/$K$6, 0) -> 0.028805992
B24: FALSE | C24: Account 2 | D24: =Budgeting!B29 -> Debt | G24: {=INDEX('⚙️Setup'!$D$2:$F$2, MAX(IF('⚙️Setup'!$D$3:$F$25=D24, COLUMN('⚙️Setup'!$D$3:$F$25)-COLUMN('⚙️Setup'!$D$3)+1)))} -> Needs | H24: =G24 -> Needs | J24: {=IFERROR(INDEX(Budgeting!$C$5:$N$42, MATCH(D24, Budgeting!$B$5:$B$42, 0), MATCH($K$2, Budgeting!$C$2:$N$2, 0)), 0)} -> 0 | K24: =IFERROR(J24/$K$6, 0) -> 0
B25: FALSE | C25: Account 2 | D25: =Budgeting!B30 -> Needs 8 | G25: {=INDEX('⚙️Setup'!$D$2:$F$2, MAX(IF('⚙️Setup'!$D$3:$F$25=D25, COLUMN('⚙️Setup'!$D$3:$F$25)-COLUMN('⚙️Setup'!$D$3)+1)))} -> Needs | H25: =G25 -> Needs | J25: {=IFERROR(INDEX(Budgeting!$C$5:$N$42, MATCH(D25, Budgeting!$B$5:$B$42, 0), MATCH($K$2, Budgeting!$C$2:$N$2, 0)), 0)} | K25: =IFERROR(J25/$K$6, 0) -> 0
B26: FALSE | C26: BCA | D26: =Budgeting!B31 -> Needs 9 | G26: {=INDEX('⚙️Setup'!$D$2:$F$2, MAX(IF('⚙️Setup'!$D$3:$F$25=D26, COLUMN('⚙️Setup'!$D$3:$F$25)-COLUMN('⚙️Setup'!$D$3)+1)))} -> Needs | H26: =G26 -> Needs | J26: {=IFERROR(INDEX(Budgeting!$C$5:$N$42, MATCH(D26, Budgeting!$B$5:$B$42, 0), MATCH($K$2, Budgeting!$C$2:$N$2, 0)), 0)} | K26: =IFERROR(J26/$K$6, 0) -> 0
B27: FALSE | C27: Account 2 | D27: =Budgeting!B32 -> Needs 10 | G27: {=INDEX('⚙️Setup'!$D$2:$F$2, MAX(IF('⚙️Setup'!$D$3:$F$25=D27, COLUMN('⚙️Setup'!$D$3:$F$25)-COLUMN('⚙️Setup'!$D$3)+1)))} -> Needs | H27: =G27 -> Needs | J27: {=IFERROR(INDEX(Budgeting!$C$5:$N$42, MATCH(D27, Budgeting!$B$5:$B$42, 0), MATCH($K$2, Budgeting!$C$2:$N$2, 0)), 0)} | K27: =IFERROR(J27/$K$6, 0) -> 0
B28: FALSE | C28: BCA | D28: =Budgeting!B33 -> Shopping | G28: {=INDEX('⚙️Setup'!$D$2:$F$2, MAX(IF('⚙️Setup'!$D$3:$F$25=D28, COLUMN('⚙️Setup'!$D$3:$F$25)-COLUMN('⚙️Setup'!$D$3)+1)))} -> Wants | H28: =G28 -> Wants | J28: {=IFERROR(INDEX(Budgeting!$C$5:$N$42, MATCH(D28, Budgeting!$B$5:$B$42, 0), MATCH($K$2, Budgeting!$C$2:$N$2, 0)), 0)} -> 200000 | K28: =IFERROR(J28/$K$6, 0) -> 0.028805992
B29: FALSE | C29: BCA | D29: =Budgeting!B34 -> Entertaiment | G29: {=INDEX('⚙️Setup'!$D$2:$F$2, MAX(IF('⚙️Setup'!$D$3:$F$25=D29, COLUMN('⚙️Setup'!$D$3:$F$25)-COLUMN('⚙️Setup'!$D$3)+1)))} -> Wants | H29: =G29 -> Wants | J29: {=IFERROR(INDEX(Budgeting!$C$5:$N$42, MATCH(D29, Budgeting!$B$5:$B$42, 0), MATCH($K$2, Budgeting!$C$2:$N$2, 0)), 0)} -> 200000 | K29: =IFERROR(J29/$K$6, 0) -> 0.028805992
B30: FALSE | C30: Account 2 | D30: =Budgeting!B35 -> Gifts | G30: {=INDEX('⚙️Setup'!$D$2:$F$2, MAX(IF('⚙️Setup'!$D$3:$F$25=D30, COLUMN('⚙️Setup'!$D$3:$F$25)-COLUMN('⚙️Setup'!$D$3)+1)))} -> Wants | H30: =G30 -> Wants | J30: {=IFERROR(INDEX(Budgeting!$C$5:$N$42, MATCH(D30, Budgeting!$B$5:$B$42, 0), MATCH($K$2, Budgeting!$C$2:$N$2, 0)), 0)} -> 150000 | K30: =IFERROR(J30/$K$6, 0) -> 0.021604494
B31: FALSE | C31: Account 3 | D31: =Budgeting!B36 -> Travel | G31: {=INDEX('⚙️Setup'!$D$2:$F$2, MAX(IF('⚙️Setup'!$D$3:$F$25=D31, COLUMN('⚙️Setup'!$D$3:$F$25)-COLUMN('⚙️Setup'!$D$3)+1)))} -> Wants | H31: =G31 -> Wants | J31: {=IFERROR(INDEX(Budgeting!$C$5:$N$42, MATCH(D31, Budgeting!$B$5:$B$42, 0), MATCH($K$2, Budgeting!$C$2:$N$2, 0)), 0)} | K31: =IFERROR(J31/$K$6, 0) -> 0
B32: FALSE | C32: BCA | D32: =Budgeting!B37 -> Wants 5 | G32: {=INDEX('⚙️Setup'!$D$2:$F$2, MAX(IF('⚙️Setup'!$D$3:$F$25=D32, COLUMN('⚙️Setup'!$D$3:$F$25)-COLUMN('⚙️Setup'!$D$3)+1)))} -> Wants | H32: =G32 -> Wants | J32: {=IFERROR(INDEX(Budgeting!$C$5:$N$42, MATCH(D32, Budgeting!$B$5:$B$42, 0), MATCH($K$2, Budgeting!$C$2:$N$2, 0)), 0)} | K32: =IFERROR(J32/$K$6, 0) -> 0
... B36: FALSE | C36: BCA | D36: =Budgeting!B41 -> Wants 9 | G36: {=INDEX('⚙️Setup'!$D$2:$F$2, MAX(IF('⚙️Setup'!$D$3:$F$25=D36, COLUMN('⚙️Setup'!$D$3:$F$25)-COLUMN('⚙️Setup'!$D$3)+1)))} -> Wants | H36: =G36 -> Wants | J36: {=IFERROR(INDEX(Budgeting!$C$5:$N$42, MATCH(D36, Budgeting!$B$5:$B$42, 0), MATCH($K$2, Budgeting!$C$2:$N$2, 0)), 0)} | K36: =IFERROR(J36/$K$6, 0) -> 0

Sheet Budgeting
B2: Month ➠ | C2: ='⚙️Setup'!H3 -> January | D2: ='⚙️Setup'!H4 -> February | E2: ='⚙️Setup'!H5 -> March | F2: ='⚙️Setup'!H6 -> April | G2: ='⚙️Setup'!H7 -> May | H2: ='⚙️Setup'!H8 -> June | I2: ='⚙️Setup'!H9 -> July | J2: ='⚙️Setup'!H10 -> August | K2: ='⚙️Setup'!H11 -> September | L2: ='⚙️Setup'!H12 -> October | M2: ='⚙️Setup'!H13 -> November | N2: ='⚙️Setup'!H14 -> December
B4: Income Sources
B5: ='⚙️Setup'!C3 -> Monthly Salary | C5: 6593000
B6: ='⚙️Setup'!C4 -> Freelance Fee | C6: 350000
B7: ='⚙️Setup'!C5 -> Income 3
B8: ='⚙️Setup'!C6 -> Income 4
B9: ='⚙️Setup'!C7 -> Income 5
B10: Total | C10: =SUM(C5:C9) -> 6943000 | D10: =SUM(D5:D9) -> 0 | E10: =SUM(E5:E9) -> 0 | F10: =SUM(F5:F9) -> 0 | G10: =SUM(G5:G9) -> 0 | H10: =SUM(H5:H9) -> 0 | I10: =SUM(I5:I9) -> 0 | J10: =SUM(J5:J9) -> 0 | ... N10: =SUM(N5:N9) -> 0
B12: Savings List
B13: ='⚙️Setup'!F3 -> General Savings | C13: 10000000
B14: ='⚙️Setup'!F4 -> Emergency Funds | C14: 5000000
B15: ='⚙️Setup'!F5 -> Deposits | C15: 328982000
B16: ='⚙️Setup'!F6 -> Savings 4
B17: ='⚙️Setup'!F6 -> Savings 4
B18: ='⚙️Setup'!F7 -> Savings 5
B19: Total | C19: =SUM(C13:C18) -> 343982000 | D19: =SUM(D13:D18) -> 0 | E19: =SUM(E13:E18) -> 0 | F19: =SUM(F13:F18) -> 0 | G19: =SUM(G13:G18) -> 0 | H19: =SUM(H13:H18) -> 0 | I19: =SUM(I13:I18) -> 0 | J19: =SUM(J13:J18) -> 0 | ... N19: =SUM(N13:N18) -> 0
B20: Grand Total | C20: =C19 -> 343982000 | D20: =C20+D19 -> 343982000 | E20: =D20+E19 -> 343982000 | F20: =E20+F19+ N("AndBV3") -> 343982000 | G20: =F20+G19 -> 343982000 | H20: =G20+H19 -> 343982000 | I20: =H20+I19 -> 343982000 | J20: =I20+J19 -> 343982000 | K20: =J20+K19 -> 343982000 | L20: =K20+L19 -> 343982000 | M20: =L20+M19 -> 343982000 | N20: =M20+N19 -> 343982000
B22: Budgeting List
B23: ='⚙️Setup'!D3 -> Family | C23: 500000
B24: ='⚙️Setup'!D4 -> Utilities | C24: 500000
B25: ='⚙️Setup'!D5 -> Food | C25: 600000
B26: ='⚙️Setup'!D6 -> Supplies | C26: 500000
B27: ='⚙️Setup'!D7 -> Transportation | C27: 400000
B28: ='⚙️Setup'!D8 -> Healthcare | C28: 200000
B29: ='⚙️Setup'!D9 -> Debt | C29: 0
B30: ='⚙️Setup'!D10 -> Needs 8
B31: ='⚙️Setup'!D11 -> Needs 9
B32: ='⚙️Setup'!D12 -> Needs 10
B33: ='⚙️Setup'!E3 -> Shopping | C33: 200000
B34: ='⚙️Setup'!E4 -> Entertaiment | C34: 200000
B35: ='⚙️Setup'!E5 -> Gifts | C35: 150000
B36: ='⚙️Setup'!E6 -> Travel
B37: ='⚙️Setup'!E7 -> Wants 5
B38: ='⚙️Setup'!E8 -> Wants 6
B39: ='⚙️Setup'!E9 -> Wants 7
B40: ='⚙️Setup'!E10 -> Wants 8
B41: ='⚙️Setup'!E11 -> Wants 9
B42: ='⚙️Setup'!E12 -> Wants 10
B43: Total | C43: =SUM(C23:C42) -> 3250000 | D43: =SUM(D23:D42) -> 0 | E43: =SUM(E23:E42) -> 0 | F43: =SUM(F23:F42) -> 0 | G43: =SUM(G23:G42) -> 0 | H43: =SUM(H23:H42) -> 0 | I43: =SUM(I23:I42) -> 0 | J43: =SUM(J23:J42) -> 0 | ... N43: =SUM(N23:N42) -> 0
B45: Allocated Money | C45: =IFERROR((C43+C19)/C10,"N/A") -> 50.01181 | D45: =IFERROR((D43+D19)/D10,"N/A") -> N/A | E45: =IFERROR((E43+E19)/E10,"N/A") -> N/A | F45: =IFERROR((F43+F19)/F10,"N/A") -> N/A | G45: =IFERROR((G43+G19)/G10,"N/A") -> N/A | H45: =IFERROR((H43+H19)/H10,"N/A") -> N/A | I45: =IFERROR((I43+I19)/I10,"N/A") -> N/A | J45: =IFERROR((J43+J19)/J10,"N/A") -> N/A | ... N45: =IFERROR((N43+N19)/N10,"N/A") -> N/A
...

Sheet Spending
B2: Spending Tracker Sheet
B4: Date: | C4: =TODAY() -> 46317
B6: ✓ | C6: Date | D6: Description | F6: Category | G6: Total
B8: FALSE | C8: 45292 | D8: Alokasi makan seminggu | F8: Food | G8: 300000
B9: FALSE | C9: 45293 | D9: Belanja kebutuhan rumah bulanan | F9: Supplies | G9: 300000
B10: FALSE | C10: 45294 | D10: Ke Dufan | F10: Entertaiment | G10: 178000
B11: FALSE | C11: 45295 | D11: Transportasi Umum | F11: Transportation | G11: 280000
B12: FALSE | C12: 45296 | D12: Nongkrong sama Danan, Miya, Tanish | F12: Food | G12: 75000
B13: FALSE | C13: 45297 | D13: Beli obat di Halodoc | F13: Healthcare | G13: 100000
B14: FALSE | C14: 45298 | D14: Tambahan belanja bulanan | F14: Supplies | G14: 100000
B15: FALSE | C15: 45299 | D15: Beli tempe pasar | F15: Food | G15: 10000
B16: FALSE | C16: 45300 | D16: Beli bahan kue | F16: Food | G16: 88000
B17: FALSE | C17: 45301 | D17: Topup emoney | F17: Transportation | G17: 102500
B18: FALSE | C18: 45302 | D18: Beli token listrik | F18: Utilities | G18: 500000
B19: FALSE | C19: 45322
B20: FALSE
B21: FALSE
B22: FALSE
B23: FALSE
B24: FALSE
B25: FALSE
B26: FALSE
B27: FALSE
B28: FALSE
B29: FALSE
B30: FALSE
B31: FALSE
... B981: FALSE

Sheet Assets
B2: Home Sweet Home
D5: Last update | E5: Target | G5: Progress
D6: 45292 | E6: 1500000000 | G6: =D8/E6 -> 0.22371667
D8: =sum(D21:D30)+sum(J21:K30) -> 335575000
D10: Total Assets Value
B15: Liquid Assets | G15: Non-Liquid Assets:
B16: ='⚙️Setup'!G3 -> Account 1 | C16: ='⚙️Setup'!G4 -> Account 2 | D16: ='⚙️Setup'!G5 -> Account 3 | E16: ='⚙️Setup'!G6 -> Account 4 | G16: ='⚙️Setup'!G7 -> Saldo BPJS | H16: ='⚙️Setup'!G8 -> Saham | J16: ='⚙️Setup'!G9 -> Obligasi | L16: ='⚙️Setup'!G10 -> Reksa Dana
B17: =SUMPRODUCT($D$21:$D$30*($E$21:$E$30=B16)) + SUMPRODUCT($J$21:$J$30*($L$21:$L$30=B16)) -> 6593000 | C17: =SUMPRODUCT($D$21:$D$30*($E$21:$E$30=C16)) + SUMPRODUCT($J$21:$J$30*($L$21:$L$30=C16)) -> 328982000 | D17: =SUMPRODUCT($D$21:$D$30*($E$21:$E$30=D16)) + SUMPRODUCT($J$21:$J$30*($L$21:$L$30=D16)) -> 0 | E17: =SUMPRODUCT($D$21:$D$30*($E$21:$E$30=E16)) + SUMPRODUCT($J$21:$J$30*($L$21:$L$30=E16)) -> 0 | G17: =SUMPRODUCT($D$21:$D$30*($E$21:$E$30=G16)) + SUMPRODUCT($J$21:$J$30*($L$21:$L$30=G16)) -> 0 | H17: =SUMPRODUCT($D$21:$D$30*($E$21:$E$30=H16)) + SUMPRODUCT($J$21:$J$30*($L$21:$L$30=H16)) -> 0 | J17: =SUMPRODUCT($D$21:$D$30*($E$21:$E$30=J16)) + SUMPRODUCT($J$21:$J$30*($L$21:$L$30=J16)) -> 0 | L17: =SUMPRODUCT($D$21:$D$30*($E$21:$E$30=L16)) + SUMPRODUCT($J$21:$J$30*($L$21:$L$30=L16)) -> 0
B19: Liquid Assets | G19: Non-Liquid Assets:
B20: Descriptions | D20: Value | E20: Account | G20: Descriptions | J20: Value | L20: Account
B21: Gaji Bulanan | D21: 6593000 | E21: Account 1 | G21: Saldo BPJS | J21: 0 | L21: Account 3
B22: Tabungan | D22: 328982000 | E22: Account 2 | G22: Saham | J22: 0 | L22: Account 2
B23: Add Yours | E23: Account 3 | G23: Add Yours | J23: 0 | L23: Account 3
B24: Add Yours | E24: Account 4 | G24: Add Yours | J24: 0 | L24: Account 4
B25: Add Yours | G25: Add Yours
B26: Add Yours | G26: Add Yours
B27: Add Yours | G27: Add Yours
B28: Add Yours | G28: Add Yours
B29: Add Yours | G29: Add Yours
B30: Add Yours | G30: Add Yours
B32: Month | C32: Total Income | D32: Savings | E32: Expenses
B33: ='⚙️Setup'!H3 -> January | C33: =Budgeting!C10 -> 6943000 | D33: =Budgeting!C19 -> 343982000 | E33: =Snapshot!C34 -> 2033500
B34: ='⚙️Setup'!H4 -> February | C34: =Budgeting!D10 -> 0 | D34: =Budgeting!D19 -> 0 | E34: =Snapshot!D34 -> 0
B35: ='⚙️Setup'!H5 -> March | C35: =Budgeting!E10 -> 0 | D35: =Budgeting!E19 -> 0 | E35: =Snapshot!E34 -> 0
B36: ='⚙️Setup'!H6 -> April | C36: =Budgeting!F10 -> 0 | D36: =Budgeting!F19 -> 0 | E36: =Snapshot!F34 -> 0
B37: ='⚙️Setup'!H7 -> May | C37: =Budgeting!G10 -> 0 | D37: =Budgeting!G19 -> 0 | E37: =Snapshot!G34 -> 0
B38: ='⚙️Setup'!H8 -> June | C38: =Budgeting!H10 -> 0 | D38: =Budgeting!H19 -> 0 | E38: =Snapshot!H34 -> 0
B39: ='⚙️Setup'!H9 -> July | C39: =Budgeting!I10 -> 0 | D39: =Budgeting!I19 -> 0 | E39: =Snapshot!I34 -> 0
B40: ='⚙️Setup'!H10 -> August | C40: =Budgeting!J10 -> 0 | D40: =Budgeting!J19 -> 0 | E40: =Snapshot!J34 -> 0
B41: ='⚙️Setup'!H11 -> September | C41: =Budgeting!K10 -> 0 | D41: =Budgeting!K19 -> 0 | E41: =Snapshot!K34 -> 0
B42: ='⚙️Setup'!H12 -> October | C42: =Budgeting!L10 -> 0 | D42: =Budgeting!L19 -> 0 | E42: =Snapshot!L34 -> 0
B43: ='⚙️Setup'!H13 -> November | C43: =Budgeting!M10 -> 0 | D43: =Budgeting!M19 -> 0 | E43: =Snapshot!M34 -> 0
B44: ='⚙️Setup'!H14 -> December | C44: =Budgeting!N10 -> 0 | D44: =Budgeting!N19 -> 0 | E44: =Snapshot!N34 -> 0
B45: TOTAL

Sheet Snapshot
B2: Month ➠ | C2: ='⚙️Setup'!H3 -> January | D2: ='⚙️Setup'!H4 -> February | E2: ='⚙️Setup'!H5 -> March | F2: ='⚙️Setup'!H6 -> April | G2: ='⚙️Setup'!H7 -> May | H2: ='⚙️Setup'!H8 -> June | I2: ='⚙️Setup'!H9 -> July | J2: ='⚙️Setup'!H10 -> August | K2: ='⚙️Setup'!H11 -> September | L2: ='⚙️Setup'!H12 -> October | M2: ='⚙️Setup'!H13 -> November | N2: ='⚙️Setup'!H14 -> December
B4: Income
B6: Total Income | C6: =Budgeting!C10 -> 6943000 | D6: =Budgeting!D10 -> 0 | E6: =Budgeting!E10 -> 0 | F6: =Budgeting!F10 -> 0 | G6: =Budgeting!G10 -> 0 | H6: =Budgeting!H10 -> 0 | I6: =Budgeting!I10 -> 0 | J6: =Budgeting!J10 -> 0 | ... N6: =Budgeting!N10 -> 0
B8: Savings
B10: Total Savings | C10: =Budgeting!C20 -> 343982000 | D10: =Budgeting!D20 -> 343982000 | E10: =Budgeting!E20 -> 343982000 | F10: =Budgeting!F20 -> 343982000 | G10: =Budgeting!G20 -> 343982000 | H10: =Budgeting!H20 -> 343982000 | I10: =Budgeting!I20 -> 343982000 | J10: =Budgeting!J20 -> 343982000 | ... N10: =Budgeting!N20 -> 343982000
B12: Expenses Snapshot
B14: =Budgeting!B23 -> Family | C14: =SUMPRODUCT((TEXT(Spending!$C:$C, "mmmm") = C$2) * (Spending!$F:$F = $B14), Spending!$G:$G) -> 0 | D14: =SUMPRODUCT((TEXT(Spending!$C:$C, "mmmm") = D$2) * (Spending!$F:$F = $B14), Spending!$G:$G) -> 0 | E14: =SUMPRODUCT((TEXT(Spending!$C:$C, "mmmm") = E$2) * (Spending!$F:$F = $B14), Spending!$G:$G) -> 0 | F14: =SUMPRODUCT((TEXT(Spending!$C:$C, "mmmm") = F$2) * (Spending!$F:$F = $B14), Spending!$G:$G) -> 0 | G14: =SUMPRODUCT((TEXT(Spending!$C:$C, "mmmm") = G$2) * (Spending!$F:$F = $B14), Spending!$G:$G) -> 0 | H14: =SUMPRODUCT((TEXT(Spending!$C:$C, "mmmm") = H$2) * (Spending!$F:$F = $B14), Spending!$G:$G) -> 0 | I14: =SUMPRODUCT((TEXT(Spending!$C:$C, "mmmm") = I$2) * (Spending!$F:$F = $B14), Spending!$G:$G) -> 0 | J14: =SUMPRODUCT((TEXT(Spending!$C:$C, "mmmm") = J$2) * (Spending!$F:$F = $B14), Spending!$G:$G) -> 0 | ... N14: =SUMPRODUCT((TEXT(Spending!$C:$C, "mmmm") = N$2) * (Spending!$F:$F = $B14), Spending!$G:$G) -> 0
B15: =Budgeting!B24 -> Utilities | C15: =SUMPRODUCT((TEXT(Spending!$C:$C, "mmmm") = C$2) * (Spending!$F:$F = $B15), Spending!$G:$G) -> 500000 | D15: =SUMPRODUCT((TEXT(Spending!$C:$C, "mmmm") = D$2) * (Spending!$F:$F = $B15), Spending!$G:$G) -> 0 | E15: =SUMPRODUCT((TEXT(Spending!$C:$C, "mmmm") = E$2) * (Spending!$F:$F = $B15), Spending!$G:$G) -> 0 | F15: =SUMPRODUCT((TEXT(Spending!$C:$C, "mmmm") = F$2) * (Spending!$F:$F = $B15), Spending!$G:$G) -> 0 | G15: =SUMPRODUCT((TEXT(Spending!$C:$C, "mmmm") = G$2) * (Spending!$F:$F = $B15), Spending!$G:$G) -> 0 | H15: =SUMPRODUCT((TEXT(Spending!$C:$C, "mmmm") = H$2) * (Spending!$F:$F = $B15), Spending!$G:$G) -> 0 | I15: =SUMPRODUCT((TEXT(Spending!$C:$C, "mmmm") = I$2) * (Spending!$F:$F = $B15), Spending!$G:$G) -> 0 | J15: =SUMPRODUCT((TEXT(Spending!$C:$C, "mmmm") = J$2) * (Spending!$F:$F = $B15), Spending!$G:$G) -> 0 | ... N15: =SUMPRODUCT((TEXT(Spending!$C:$C, "mmmm") = N$2) * (Spending!$F:$F = $B15), Spending!$G:$G) -> 0
B16: =Budgeting!B25 -> Food | C16: =SUMPRODUCT((TEXT(Spending!$C:$C, "mmmm") = C$2) * (Spending!$F:$F = $B16), Spending!$G:$G) -> 473000 | D16: =SUMPRODUCT((TEXT(Spending!$C:$C, "mmmm") = D$2) * (Spending!$F:$F = $B16), Spending!$G:$G) -> 0 | E16: =SUMPRODUCT((TEXT(Spending!$C:$C, "mmmm") = E$2) * (Spending!$F:$F = $B16), Spending!$G:$G) -> 0 | F16: =SUMPRODUCT((TEXT(Spending!$C:$C, "mmmm") = F$2) * (Spending!$F:$F = $B16), Spending!$G:$G) -> 0 | G16: =SUMPRODUCT((TEXT(Spending!$C:$C, "mmmm") = G$2) * (Spending!$F:$F = $B16), Spending!$G:$G) -> 0 | H16: =SUMPRODUCT((TEXT(Spending!$C:$C, "mmmm") = H$2) * (Spending!$F:$F = $B16), Spending!$G:$G) -> 0 | I16: =SUMPRODUCT((TEXT(Spending!$C:$C, "mmmm") = I$2) * (Spending!$F:$F = $B16), Spending!$G:$G) -> 0 | J16: =SUMPRODUCT((TEXT(Spending!$C:$C, "mmmm") = J$2) * (Spending!$F:$F = $B16), Spending!$G:$G) -> 0 | ... N16: =SUMPRODUCT((TEXT(Spending!$C:$C, "mmmm") = N$2) * (Spending!$F:$F = $B16), Spending!$G:$G) -> 0
B17: =Budgeting!B26 -> Supplies | C17: =SUMPRODUCT((TEXT(Spending!$C:$C, "mmmm") = C$2) * (Spending!$F:$F = $B17), Spending!$G:$G) -> 400000 | D17: =SUMPRODUCT((TEXT(Spending!$C:$C, "mmmm") = D$2) * (Spending!$F:$F = $B17), Spending!$G:$G) -> 0 | E17: =SUMPRODUCT((TEXT(Spending!$C:$C, "mmmm") = E$2) * (Spending!$F:$F = $B17), Spending!$G:$G) -> 0 | F17: =SUMPRODUCT((TEXT(Spending!$C:$C, "mmmm") = F$2) * (Spending!$F:$F = $B17), Spending!$G:$G) -> 0 | G17: =SUMPRODUCT((TEXT(Spending!$C:$C, "mmmm") = G$2) * (Spending!$F:$F = $B17), Spending!$G:$G) -> 0 | H17: =SUMPRODUCT((TEXT(Spending!$C:$C, "mmmm") = H$2) * (Spending!$F:$F = $B17), Spending!$G:$G) -> 0 | I17: =SUMPRODUCT((TEXT(Spending!$C:$C, "mmmm") = I$2) * (Spending!$F:$F = $B17), Spending!$G:$G) -> 0 | J17: =SUMPRODUCT((TEXT(Spending!$C:$C, "mmmm") = J$2) * (Spending!$F:$F = $B17), Spending!$G:$G) -> 0 | ... N17: =SUMPRODUCT((TEXT(Spending!$C:$C, "mmmm") = N$2) * (Spending!$F:$F = $B17), Spending!$G:$G) -> 0
B18: =Budgeting!B27 -> Transportation | C18: =SUMPRODUCT((TEXT(Spending!$C:$C, "mmmm") = C$2) * (Spending!$F:$F = $B18), Spending!$G:$G) -> 382500 | D18: =SUMPRODUCT((TEXT(Spending!$C:$C, "mmmm") = D$2) * (Spending!$F:$F = $B18), Spending!$G:$G) -> 0 | E18: =SUMPRODUCT((TEXT(Spending!$C:$C, "mmmm") = E$2) * (Spending!$F:$F = $B18), Spending!$G:$G) -> 0 | F18: =SUMPRODUCT((TEXT(Spending!$C:$C, "mmmm") = F$2) * (Spending!$F:$F = $B18), Spending!$G:$G) -> 0 | G18: =SUMPRODUCT((TEXT(Spending!$C:$C, "mmmm") = G$2) * (Spending!$F:$F = $B18), Spending!$G:$G) -> 0 | H18: =SUMPRODUCT((TEXT(Spending!$C:$C, "mmmm") = H$2) * (Spending!$F:$F = $B18), Spending!$G:$G) -> 0 | I18: =SUMPRODUCT((TEXT(Spending!$C:$C, "mmmm") = I$2) * (Spending!$F:$F = $B18), Spending!$G:$G) -> 0 | J18: =SUMPRODUCT((TEXT(Spending!$C:$C, "mmmm") = J$2) * (Spending!$F:$F = $B18), Spending!$G:$G) -> 0 | ... N18: =SUMPRODUCT((TEXT(Spending!$C:$C, "mmmm") = N$2) * (Spending!$F:$F = $B18), Spending!$G:$G) -> 0
B19: =Budgeting!B28 -> Healthcare | C19: =SUMPRODUCT((TEXT(Spending!$C:$C, "mmmm") = C$2) * (Spending!$F:$F = $B19), Spending!$G:$G) -> 100000 | D19: =SUMPRODUCT((TEXT(Spending!$C:$C, "mmmm") = D$2) * (Spending!$F:$F = $B19), Spending!$G:$G) -> 0 | E19: =SUMPRODUCT((TEXT(Spending!$C:$C, "mmmm") = E$2) * (Spending!$F:$F = $B19), Spending!$G:$G) -> 0 | F19: =SUMPRODUCT((TEXT(Spending!$C:$C, "mmmm") = F$2) * (Spending!$F:$F = $B19), Spending!$G:$G) -> 0 | G19: =SUMPRODUCT((TEXT(Spending!$C:$C, "mmmm") = G$2) * (Spending!$F:$F = $B19), Spending!$G:$G) -> 0 | H19: =SUMPRODUCT((TEXT(Spending!$C:$C, "mmmm") = H$2) * (Spending!$F:$F = $B19), Spending!$G:$G) -> 0 | I19: =SUMPRODUCT((TEXT(Spending!$C:$C, "mmmm") = I$2) * (Spending!$F:$F = $B19), Spending!$G:$G) -> 0 | J19: =SUMPRODUCT((TEXT(Spending!$C:$C, "mmmm") = J$2) * (Spending!$F:$F = $B19), Spending!$G:$G) -> 0 | ... N19: =SUMPRODUCT((TEXT(Spending!$C:$C, "mmmm") = N$2) * (Spending!$F:$F = $B19), Spending!$G:$G) -> 0
B20: =Budgeting!B29 -> Debt | C20: =SUMPRODUCT((TEXT(Spending!$C:$C, "mmmm") = C$2) * (Spending!$F:$F = $B20), Spending!$G:$G) -> 0 | D20: =SUMPRODUCT((TEXT(Spending!$C:$C, "mmmm") = D$2) * (Spending!$F:$F = $B20), Spending!$G:$G) -> 0 | E20: =SUMPRODUCT((TEXT(Spending!$C:$C, "mmmm") = E$2) * (Spending!$F:$F = $B20), Spending!$G:$G) -> 0 | F20: =SUMPRODUCT((TEXT(Spending!$C:$C, "mmmm") = F$2) * (Spending!$F:$F = $B20), Spending!$G:$G) -> 0 | G20: =SUMPRODUCT((TEXT(Spending!$C:$C, "mmmm") = G$2) * (Spending!$F:$F = $B20), Spending!$G:$G) -> 0 | H20: =SUMPRODUCT((TEXT(Spending!$C:$C, "mmmm") = H$2) * (Spending!$F:$F = $B20), Spending!$G:$G) -> 0 | I20: =SUMPRODUCT((TEXT(Spending!$C:$C, "mmmm") = I$2) * (Spending!$F:$F = $B20), Spending!$G:$G) -> 0 | J20: =SUMPRODUCT((TEXT(Spending!$C:$C, "mmmm") = J$2) * (Spending!$F:$F = $B20), Spending!$G:$G) -> 0 | ... N20: =SUMPRODUCT((TEXT(Spending!$C:$C, "mmmm") = N$2) * (Spending!$F:$F = $B20), Spending!$G:$G) -> 0
B21: =Budgeting!B30 -> Needs 8 | C21: =SUMPRODUCT((TEXT(Spending!$C:$C, "mmmm") = C$2) * (Spending!$F:$F = $B21), Spending!$G:$G) -> 0 | D21: =SUMPRODUCT((TEXT(Spending!$C:$C, "mmmm") = D$2) * (Spending!$F:$F = $B21), Spending!$G:$G) -> 0 | E21: =SUMPRODUCT((TEXT(Spending!$C:$C, "mmmm") = E$2) * (Spending!$F:$F = $B21), Spending!$G:$G) -> 0 | F21: =SUMPRODUCT((TEXT(Spending!$C:$C, "mmmm") = F$2) * (Spending!$F:$F = $B21), Spending!$G:$G) -> 0 | G21: =SUMPRODUCT((TEXT(Spending!$C:$C, "mmmm") = G$2) * (Spending!$F:$F = $B21), Spending!$G:$G) -> 0 | H21: =SUMPRODUCT((TEXT(Spending!$C:$C, "mmmm") = H$2) * (Spending!$F:$F = $B21), Spending!$G:$G) -> 0 | I21: =SUMPRODUCT((TEXT(Spending!$C:$C, "mmmm") = I$2) * (Spending!$F:$F = $B21), Spending!$G:$G) -> 0 | J21: =SUMPRODUCT((TEXT(Spending!$C:$C, "mmmm") = J$2) * (Spending!$F:$F = $B21), Spending!$G:$G) -> 0 | ... N21: =SUMPRODUCT((TEXT(Spending!$C:$C, "mmmm") = N$2) * (Spending!$F:$F = $B21), Spending!$G:$G) -> 0
B22: =Budgeting!B31 -> Needs 9 | C22: =SUMPRODUCT((TEXT(Spending!$C:$C, "mmmm") = C$2) * (Spending!$F:$F = $B22), Spending!$G:$G) -> 0 | D22: =SUMPRODUCT((TEXT(Spending!$C:$C, "mmmm") = D$2) * (Spending!$F:$F = $B22), Spending!$G:$G) -> 0 | E22: =SUMPRODUCT((TEXT(Spending!$C:$C, "mmmm") = E$2) * (Spending!$F:$F = $B22), Spending!$G:$G) -> 0 | F22: =SUMPRODUCT((TEXT(Spending!$C:$C, "mmmm") = F$2) * (Spending!$F:$F = $B22), Spending!$G:$G) -> 0 | G22: =SUMPRODUCT((TEXT(Spending!$C:$C, "mmmm") = G$2) * (Spending!$F:$F = $B22), Spending!$G:$G) -> 0 | H22: =SUMPRODUCT((TEXT(Spending!$C:$C, "mmmm") = H$2) * (Spending!$F:$F = $B22), Spending!$G:$G) -> 0 | I22: =SUMPRODUCT((TEXT(Spending!$C:$C, "mmmm") = I$2) * (Spending!$F:$F = $B22), Spending!$G:$G) -> 0 | J22: =SUMPRODUCT((TEXT(Spending!$C:$C, "mmmm") = J$2) * (Spending!$F:$F = $B22), Spending!$G:$G) -> 0 | ... N22: =SUMPRODUCT((TEXT(Spending!$C:$C, "mmmm") = N$2) * (Spending!$F:$F = $B22), Spending!$G:$G) -> 0
B23: =Budgeting!B32 -> Needs 10 | C23: =SUMPRODUCT((TEXT(Spending!$C:$C, "mmmm") = C$2) * (Spending!$F:$F = $B23), Spending!$G:$G) -> 0 | D23: =SUMPRODUCT((TEXT(Spending!$C:$C, "mmmm") = D$2) * (Spending!$F:$F = $B23), Spending!$G:$G) -> 0 | E23: =SUMPRODUCT((TEXT(Spending!$C:$C, "mmmm") = E$2) * (Spending!$F:$F = $B23), Spending!$G:$G) -> 0 | F23: =SUMPRODUCT((TEXT(Spending!$C:$C, "mmmm") = F$2) * (Spending!$F:$F = $B23), Spending!$G:$G) -> 0 | G23: =SUMPRODUCT((TEXT(Spending!$C:$C, "mmmm") = G$2) * (Spending!$F:$F = $B23), Spending!$G:$G) -> 0 | H23: =SUMPRODUCT((TEXT(Spending!$C:$C, "mmmm") = H$2) * (Spending!$F:$F = $B23), Spending!$G:$G) -> 0 | I23: =SUMPRODUCT((TEXT(Spending!$C:$C, "mmmm") = I$2) * (Spending!$F:$F = $B23), Spending!$G:$G) -> 0 | J23: =SUMPRODUCT((TEXT(Spending!$C:$C, "mmmm") = J$2) * (Spending!$F:$F = $B23), Spending!$G:$G) -> 0 | ... N23: =SUMPRODUCT((TEXT(Spending!$C:$C, "mmmm") = N$2) * (Spending!$F:$F = $B23), Spending!$G:$G) -> 0
B24: =Budgeting!B33 -> Shopping | C24: =SUMPRODUCT((TEXT(Spending!$C:$C, "mmmm") = C$2) * (Spending!$F:$F = $B24), Spending!$G:$G) -> 0 | D24: =SUMPRODUCT((TEXT(Spending!$C:$C, "mmmm") = D$2) * (Spending!$F:$F = $B24), Spending!$G:$G) -> 0 | E24: =SUMPRODUCT((TEXT(Spending!$C:$C, "mmmm") = E$2) * (Spending!$F:$F = $B24), Spending!$G:$G) -> 0 | F24: =SUMPRODUCT((TEXT(Spending!$C:$C, "mmmm") = F$2) * (Spending!$F:$F = $B24), Spending!$G:$G) -> 0 | G24: =SUMPRODUCT((TEXT(Spending!$C:$C, "mmmm") = G$2) * (Spending!$F:$F = $B24), Spending!$G:$G) -> 0 | H24: =SUMPRODUCT((TEXT(Spending!$C:$C, "mmmm") = H$2) * (Spending!$F:$F = $B24), Spending!$G:$G) -> 0 | I24: =SUMPRODUCT((TEXT(Spending!$C:$C, "mmmm") = I$2) * (Spending!$F:$F = $B24), Spending!$G:$G) -> 0 | J24: =SUMPRODUCT((TEXT(Spending!$C:$C, "mmmm") = J$2) * (Spending!$F:$F = $B24), Spending!$G:$G) -> 0 | ... N24: =SUMPRODUCT((TEXT(Spending!$C:$C, "mmmm") = N$2) * (Spending!$F:$F = $B24), Spending!$G:$G) -> 0
B25: =Budgeting!B34 -> Entertaiment | C25: =SUMPRODUCT((TEXT(Spending!$C:$C, "mmmm") = C$2) * (Spending!$F:$F = $B25), Spending!$G:$G) -> 178000 | D25: =SUMPRODUCT((TEXT(Spending!$C:$C, "mmmm") = D$2) * (Spending!$F:$F = $B25), Spending!$G:$G) -> 0 | E25: =SUMPRODUCT((TEXT(Spending!$C:$C, "mmmm") = E$2) * (Spending!$F:$F = $B25), Spending!$G:$G) -> 0 | F25: =SUMPRODUCT((TEXT(Spending!$C:$C, "mmmm") = F$2) * (Spending!$F:$F = $B25), Spending!$G:$G) -> 0 | G25: =SUMPRODUCT((TEXT(Spending!$C:$C, "mmmm") = G$2) * (Spending!$F:$F = $B25), Spending!$G:$G) -> 0 | H25: =SUMPRODUCT((TEXT(Spending!$C:$C, "mmmm") = H$2) * (Spending!$F:$F = $B25), Spending!$G:$G) -> 0 | I25: =SUMPRODUCT((TEXT(Spending!$C:$C, "mmmm") = I$2) * (Spending!$F:$F = $B25), Spending!$G:$G) -> 0 | J25: =SUMPRODUCT((TEXT(Spending!$C:$C, "mmmm") = J$2) * (Spending!$F:$F = $B25), Spending!$G:$G) -> 0 | ... N25: =SUMPRODUCT((TEXT(Spending!$C:$C, "mmmm") = N$2) * (Spending!$F:$F = $B25), Spending!$G:$G) -> 0
... B33: =Budgeting!B42 -> Wants 10 | C33: =SUMPRODUCT((TEXT(Spending!$C:$C, "mmmm") = C$2) * (Spending!$F:$F = $B33), Spending!$G:$G) -> 0 | D33: =SUMPRODUCT((TEXT(Spending!$C:$C, "mmmm") = D$2) * (Spending!$F:$F = $B33), Spending!$G:$G) -> 0 | E33: =SUMPRODUCT((TEXT(Spending!$C:$C, "mmmm") = E$2) * (Spending!$F:$F = $B33), Spending!$G:$G) -> 0 | F33: =SUMPRODUCT((TEXT(Spending!$C:$C, "mmmm") = F$2) * (Spending!$F:$F = $B33), Spending!$G:$G) -> 0 | G33: =SUMPRODUCT((TEXT(Spending!$C:$C, "mmmm") = G$2) * (Spending!$F:$F = $B33), Spending!$G:$G) -> 0 | H33: =SUMPRODUCT((TEXT(Spending!$C:$C, "mmmm") = H$2) * (Spending!$F:$F = $B33), Spending!$G:$G) -> 0 | I33: =SUMPRODUCT((TEXT(Spending!$C:$C, "mmmm") = I$2) * (Spending!$F:$F = $B33), Spending!$G:$G) -> 0 | J33: =SUMPRODUCT((TEXT(Spending!$C:$C, "mmmm") = J$2) * (Spending!$F:$F = $B33), Spending!$G:$G) -> 0 | ... N33: =SUMPRODUCT((TEXT(Spending!$C:$C, "mmmm") = N$2) * (Spending!$F:$F = $B33), Spending!$G:$G) -> 0
B34: Total | C34: =SUM(C14:C33) -> 2033500 | D34: =SUM(D14:D33) -> 0 | E34: =SUM(E14:E33) -> 0 | F34: =SUM(F14:F33) -> 0 | G34: =SUM(G14:G33) -> 0 | H34: =SUM(H14:H33) -> 0 | I34: =SUM(I14:I33) -> 0 | J34: =SUM(J14:J33) -> 0 | ... N34: =SUM(N14:N33) -> 0
B36: Remaining Funds
B38: =Budgeting!B23 -> Family | C38: =Budgeting!C23-C14 -> 500000 | D38: =Budgeting!D23-D14 -> 0 | E38: =Budgeting!E23-E14 -> 0 | F38: =Budgeting!F23-F14 -> 0 | G38: =Budgeting!G23-G14 -> 0 | H38: =Budgeting!H23-H14 -> 0 | I38: =Budgeting!I23-I14 -> 0 | J38: =Budgeting!J23-J14 -> 0 | ... N38: =Budgeting!N23-N14 -> 0
B39: =Budgeting!B24 -> Utilities | C39: =Budgeting!C24-C15 -> 0 | D39: =Budgeting!D24-D15 -> 0 | E39: =Budgeting!E24-E15 -> 0 | F39: =Budgeting!F24-F15 -> 0 | G39: =Budgeting!G24-G15 -> 0 | H39: =Budgeting!H24-H15 -> 0 | I39: =Budgeting!I24-I15 -> 0 | J39: =Budgeting!J24-J15 -> 0 | ... N39: =Budgeting!N24-N15 -> 0
B40: =Budgeting!B25 -> Food | C40: =Budgeting!C25-C16 -> 127000 | D40: =Budgeting!D25-D16 -> 0 | E40: =Budgeting!E25-E16 -> 0 | F40: =Budgeting!F25-F16 -> 0 | G40: =Budgeting!G25-G16 -> 0 | H40: =Budgeting!H25-H16 -> 0 | I40: =Budgeting!I25-I16 -> 0 | J40: =Budgeting!J25-J16 -> 0 | ... N40: =Budgeting!N25-N16 -> 0
B41: =Budgeting!B26 -> Supplies | C41: =Budgeting!C26-C17 -> 100000 | D41: =Budgeting!D26-D17 -> 0 | E41: =Budgeting!E26-E17 -> 0 | F41: =Budgeting!F26-F17 -> 0 | G41: =Budgeting!G26-G17 -> 0 | H41: =Budgeting!H26-H17 -> 0 | I41: =Budgeting!I26-I17 -> 0 | J41: =Budgeting!J26-J17 -> 0 | ... N41: =Budgeting!N26-N17 -> 0
B42: =Budgeting!B27 -> Transportation | C42: =Budgeting!C27-C18 -> 17500 | D42: =Budgeting!D27-D18 -> 0 | E42: =Budgeting!E27-E18 -> 0 | F42: =Budgeting!F27-F18 -> 0 | G42: =Budgeting!G27-G18 -> 0 | H42: =Budgeting!H27-H18 -> 0 | I42: =Budgeting!I27-I18 -> 0 | J42: =Budgeting!J27-J18 -> 0 | ... N42: =Budgeting!N27-N18 -> 0
B43: =Budgeting!B28 -> Healthcare | C43: =Budgeting!C28-C19 -> 100000 | D43: =Budgeting!D28-D19 -> 0 | E43: =Budgeting!E28-E19 -> 0 | F43: =Budgeting!F28-F19 -> 0 | G43: =Budgeting!G28-G19 -> 0 | H43: =Budgeting!H28-H19 -> 0 | I43: =Budgeting!I28-I19 -> 0 | J43: =Budgeting!J28-J19 -> 0 | ... N43: =Budgeting!N28-N19 -> 0
B44: =Budgeting!B29 -> Debt | C44: =Budgeting!C29-C20 -> 0 | D44: =Budgeting!D29-D20 -> 0 | E44: =Budgeting!E29-E20 -> 0 | F44: =Budgeting!F29-F20 -> 0 | G44: =Budgeting!G29-G20 -> 0 | H44: =Budgeting!H29-H20 -> 0 | I44: =Budgeting!I29-I20 -> 0 | J44: =Budgeting!J29-J20 -> 0 | ... N44: =Budgeting!N29-N20 -> 0
B45: =Budgeting!B30 -> Needs 8 | C45: =Budgeting!C30-C21 -> 0 | D45: =Budgeting!D30-D21 -> 0 | E45: =Budgeting!E30-E21 -> 0 | F45: =Budgeting!F30-F21 -> 0 | G45: =Budgeting!G30-G21 -> 0 | H45: =Budgeting!H30-H21 -> 0 | I45: =Budgeting!I30-I21 -> 0 | J45: =Budgeting!J30-J21 -> 0 | ... N45: =Budgeting!N30-N21 -> 0
B46: =Budgeting!B31 -> Needs 9 | C46: =Budgeting!C31-C22 -> 0 | D46: =Budgeting!D31-D22 -> 0 | E46: =Budgeting!E31-E22 -> 0 | F46: =Budgeting!F31-F22 -> 0 | G46: =Budgeting!G31-G22 -> 0 | H46: =Budgeting!H31-H22 -> 0 | I46: =Budgeting!I31-I22 -> 0 | J46: =Budgeting!J31-J22 -> 0 | ... N46: =Budgeting!N31-N22 -> 0
B47: =Budgeting!B32 -> Needs 10 | C47: =Budgeting!C32-C23 -> 0 | D47: =Budgeting!D32-D23 -> 0 | E47: =Budgeting!E32-E23 -> 0 | F47: =Budgeting!F32-F23 -> 0 | G47: =Budgeting!G32-G23 -> 0 | H47: =Budgeting!H32-H23 -> 0 | I47: =Budgeting!I32-I23 -> 0 | J47: =Budgeting!J32-J23 -> 0 | ... N47: =Budgeting!N32-N23 -> 0
B48: =Budgeting!B33 -> Shopping | C48: =Budgeting!C33-C24 -> 200000 | D48: =Budgeting!D33-D24 -> 0 | E48: =Budgeting!E33-E24 -> 0 | F48: =Budgeting!F33-F24 -> 0 | G48: =Budgeting!G33-G24 -> 0 | H48: =Budgeting!H33-H24 -> 0 | I48: =Budgeting!I33-I24 -> 0 | J48: =Budgeting!J33-J24 -> 0 | ... N48: =Budgeting!N33-N24 -> 0
B49: =Budgeting!B34 -> Entertaiment | C49: =Budgeting!C34-C25 -> 22000 | D49: =Budgeting!D34-D25 -> 0 | E49: =Budgeting!E34-E25 -> 0 | F49: =Budgeting!F34-F25 -> 0 | G49: =Budgeting!G34-G25 -> 0 | H49: =Budgeting!H34-H25 -> 0 | I49: =Budgeting!I34-I25 -> 0 | J49: =Budgeting!J34-J25 -> 0 | ... N49: =Budgeting!N34-N25 -> 0
... B57: =Budgeting!B42 -> Wants 10 | C57: =Budgeting!C42-C33 -> 0 | D57: =Budgeting!D42-D33 -> 0 | E57: =Budgeting!E42-E33 -> 0 | F57: =Budgeting!F42-F33 -> 0 | G57: =Budgeting!G42-G33 -> 0 | H57: =Budgeting!H42-H33 -> 0 | I57: =Budgeting!I42-I33 -> 0 | J57: =Budgeting!J42-J33 -> 0 | ... N57: =Budgeting!N42-N33 -> 0
B58: Total | C58: =SUM(C38:C57) -> 1216500 | D58: =SUM(D38:D57) -> 0 | E58: =SUM(E38:E57) -> 0 | F58: =SUM(F38:F57) -> 0 | G58: =SUM(G38:G57) -> 0 | H58: =SUM(H38:H57) -> 0 | I58: =SUM(I38:I57) -> 0 | J58: =SUM(J38:J57) -> 0 | ... N58: =SUM(N38:N57) -> 0

Sheet ⚙️Setup
B2: Account [ Summary] | C2: Income Sources [budgeting] | D2: Needs | E2: Wants | F2: Savings | G2: Account [Assets] | H2: Month | I2: Payday Date
B3: BCA | C3: Monthly Salary | D3: Family | E3: Shopping | F3: General Savings | G3: Account 1 | H3: January | I3: 45590
B4: Account 2 | C4: Freelance Fee | D4: Utilities | E4: Entertaiment | F4: Emergency Funds | G4: Account 2 | H4: February
B5: Account 3 | C5: Income 3 | D5: Food | E5: Gifts | F5: Deposits | G5: Account 3 | H5: March
C6: Income 4 | D6: Supplies | E6: Travel | F6: Savings 4 | G6: Account 4 | H6: April
C7: Income 5 | D7: Transportation | E7: Wants 5 | F7: Savings 5 | G7: Saldo BPJS | H7: May
D8: Healthcare | E8: Wants 6 | G8: Saham | H8: June
D9: Debt | E9: Wants 7 | G9: Obligasi | H9: July
D10: Needs 8 | E10: Wants 8 | G10: Reksa Dana | H10: August
D11: Needs 9 | E11: Wants 9 | G11: Deposito | H11: September
D12: Needs 10 | E12: Wants 10 | H12: October
E13: Wants 11 | H13: November
H14: December
